<?xml version="1.0"?>
<robot name="robot_sd700e" xmlns:xacro="http://ros.org/wiki/xacro">

  <xacro:property name="M_PI" value="3.1415926536"/>

  <link name="base_link">
    <inertial>
      <origin xyz="-0.0194690222590369 -0.000269188119329771 0.0669003838868867" rpy="0 0 0" />
      <mass value="0.00001" />
      <inertia ixx="0.000153169404327002" ixy="1.65882461270346E-10" ixz="4.4079170251983E-07" iyy="0.000178370863576969" iyz="-2.76318351033745E-09" izz="0.000146674461881756" />
    </inertial>
    <visual>
      <origin xyz="0 0 0" rpy="0 0 0" />
      <geometry>
        <mesh filename="package://robot_sd700e_description/meshes/base_link.STL" />
      </geometry>
      <material name="">
        <color rgba="1 1 0.501960784313725 1" />
      </material>
    </visual>
    <collision>
      <origin xyz="0 0 0" rpy="0 0 0" />
      <geometry>
        <mesh filename="package://robot_sd700e_description/meshes/base_link.STL" />
      </geometry>
    </collision>
  </link>
  <link name="link1">
    <inertial>
      <origin xyz="6.24979528711656E-05 3.54756693043516E-05 0.0929610027302797" rpy="0 0 0" />
      <mass value="0.00001" />
      <inertia ixx="4.83982220972564E-05" ixy="-1.77040002978859E-10" ixz="3.19080107721578E-11" iyy="4.76414174481088E-05" iyz="-1.87834825511904E-09" izz="3.52854220263338E-05" />
    </inertial>
    <visual>
      <origin xyz="0 0 0" rpy="0 0 0" />
      <geometry>
        <mesh filename="package://robot_sd700e_description/meshes/link1.STL" />
      </geometry>
      <material name="">
        <color rgba="1 1 0.501960784313725 1" />
      </material>
    </visual>
    <collision>
      <origin xyz="0 0 0" rpy="0 0 0" />
      <geometry>
        <mesh filename="package://robot_sd700e_description/meshes/link1.STL" />
      </geometry>
    </collision>
  </link>
  <joint name="joint1" type="revolute">
    <origin xyz="0 0 0.145" rpy="0 0 0" />
    <parent link="base_link" />
    <child link="link1" />
    <!--axis xyz="0 0 -1" /-->
    <axis xyz="0 0 1" />
    <limit lower="-2.96" upper="2.96" effort="100" velocity="1" />
  </joint>
  <link
    name="link2">
    <inertial>
      <origin xyz="0.143798658237929 3.89335646278077E-06 0.0506443388040005" rpy="0 0 0" />
      <mass value="0.00001" />
      <inertia ixx="1.85130744568751E-05" ixy="2.76195499850968E-11" ixz="6.51979051130517E-06" iyy="0.000264350143112589" iyz="2.39001383154591E-09" izz="0.000275170391285063" />
    </inertial>
    <visual>
      <origin xyz="0 0 0" rpy="0 0 0" />
      <geometry>
        <mesh  filename="package://robot_sd700e_description/meshes/link2.STL" />
      </geometry>
      <material name="">
        <color rgba="1 1 0.501960784313725 1" />
      </material>
    </visual>
    <collision>
      <origin  xyz="0 0 0" rpy="0 0 0" />
      <geometry>
        <mesh  filename="package://robot_sd700e_description/meshes/link2.STL" />
      </geometry>
    </collision>
  </link>
  <joint name="joint2" type="revolute">
    <origin xyz="0 0 0.118" rpy="1.5708 -1.5708 3.1416" />
    <!--origin xyz="0 0 0.118" rpy="${M_PI / 2} 0 0" / -->
    <parent link="link1" />
    <child link="link2" />
    <axis xyz="0 0 1" />
    <!--axis xyz="0 0 -1" /-->
    <limit lower="-1.91" upper="1.91" effort="100" velocity="1" />
  </joint>
  <link name="link3">
    <inertial>
      <origin xyz="-0.0105511176614257 0.013415825069451 -0.000783677732801621" rpy="0 0 0" />
      <mass value="0.00001" />
      <inertia ixx="2.29601047838055E-05" ixy="-1.63719092770468E-06" ixz="1.81455332745205E-07" iyy="2.1162736058193E-05" iyz="-1.71577960757657E-07" izz="2.63069623781901E-05" />
    </inertial>
    <visual>
      <origin xyz="0 0 0" rpy="0 0 0" />
      <geometry>
        <mesh  filename="package://robot_sd700e_description/meshes/link3.STL" />
      </geometry>
      <material name="">
        <color rgba="1 1 0.501960784313725 1" />
      </material>
    </visual>
    <collision>
      <origin xyz="0 0 0" rpy="0 0 0" />
      <geometry>
        <mesh filename="package://robot_sd700e_description/meshes/link3.STL" />
      </geometry>
    </collision>
  </link>
  <joint name="joint3" type="revolute">
    <origin xyz="0.35 0 0" rpy="0 0 0" />
    <parent link="link2" />
    <child link="link3" />
    <axis xyz="0 0 1" />
    <limit lower="-3.83"  upper="0.69" effort="100" velocity="1" />
  </joint>
  <link name="link4">
    <inertial>
      <origin xyz="0.00053105459778995 0.00764519471507254 0.12487741102902" rpy="0 0 0" />
      <mass value="0.00001" />
      <inertia ixx="2.35060467930339E-05" ixy="-7.80273185679067E-09" ixz="-5.33242281859617E-09" iyy="2.4038986793376E-05" iyz="-3.24930744421448E-06" izz="1.06991610028112E-05" />
    </inertial>
    <visual>
      <origin xyz="0 0 0" rpy="0 0 0" />
      <geometry>
        <mesh filename="package://robot_sd700e_description/meshes/link4.STL" />
      </geometry>
      <material name="">
        <color rgba="1 1 0.501960784313725 1" />
      </material>
    </visual>
    <collision>
      <origin xyz="0 0 0" rpy="0 0 0" />
      <geometry>
        <mesh filename="package://robot_sd700e_description/meshes/link4.STL" />
      </geometry>
    </collision>
  </link>
  <joint name="joint4" type="revolute">
    <origin xyz="0 0.08 0" rpy="-1.5708 0 0" />
    <parent link="link3" />
    <child link="link4" />
    <!--axis xyz="0 0 -1" /-->
    <axis xyz="0 0 1" />
    <limit lower="-3.22" upper="3.22" effort="100" velocity="1" />
  </joint>
  <link name="link5">
    <inertial>
      <origin xyz="5.00388331529765E-06 0.017136564860525 -0.00579159800832729" rpy="0 0 0" />
      <mass value="0.00001" />
      <inertia ixx="3.02769220666609E-06" ixy="-6.63527422862123E-09" ixz="3.06980670851299E-09" iyy="1.6973682408079E-06" iyz="-2.1985747740643E-07" izz="3.30873178682241E-06" />
    </inertial>
    <visual>
      <origin xyz="0 0 0" rpy="0 0 0" />
      <geometry>
        <mesh filename="package://robot_sd700e_description/meshes/link5.STL" />
      </geometry>
      <material name="">
        <color rgba="1 1 0.501960784313725 1" />
      </material>
    </visual>
    <collision>
      <origin xyz="0 0 0" rpy="0 0 0" />
      <geometry>
        <mesh filename="package://robot_sd700e_description/meshes/link5.STL" />
      </geometry>
    </collision>
  </link>
  <joint name="joint5" type="revolute">
    <origin xyz="0 0 0.27" rpy="1.5708 0 0" />
    <parent link="link4" />
    <child link="link5" />
    <axis xyz="0 0 1" />
    <limit lower="-2.18" upper="2.18"  effort="100" velocity="1" />
  </joint>
  <link name="link6">
    <inertial>
      <origin xyz="2.98155597433514E-18 -2.16840434497101E-17 0.013" rpy="0 0 0" />
      <mass value="0.00001" />
      <inertia ixx="5.12858666666666E-06" ixy="1.96434522866803E-23" ixz="1.31858481743306E-22" iyy="3.04650666666666E-06" iyz="-4.7358312294891E-23" izz="5.12858666666666E-06" />
    </inertial>
    <visual>
      <origin xyz="0 0 0" rpy="0 0 0" />
      <geometry>
        <mesh filename="package://robot_sd700e_description/meshes/link6.STL" />
      </geometry>
      <material name="">
        <color rgba="1 1 1 1" />
      </material>
    </visual>
    <collision>
      <origin xyz="0 0 0" rpy="0 0 0" />
      <geometry>
        <mesh filename="package://robot_sd700e_description/meshes/link6.STL" />
      </geometry>
    </collision>
  </link>
  <joint name="joint6" type="revolute">
    <origin xyz="0 0.0745 0" rpy="-1.5708 0 0" />
    <parent link="link5" />
    <child link="link6" />
    <!--axis xyz="0 0 -1" /-->
    <axis xyz="0 0 1" />
    <limit lower="-6.28" upper="6.28" effort="100" velocity="1" />
  </joint>
  <link name="link7">
    <inertial>
      <origin xyz="-2.4931047704497E-07 -0.00154228485453155 0.0894543761927693" rpy="0 0 0" />
      <mass value="0.00001" />
      <inertia ixx="2.20720617168517E-05" ixy="-1.33959955753033E-07" ixz="-4.80345012228219E-12" iyy="1.3850289704466E-05" iyz="1.22347910736772E-07" izz="2.41352773855343E-05" />
    </inertial>
    <visual>
      <origin xyz="0 0 0" rpy="0 0 0" />
      <geometry>
        <mesh filename="package://robot_sd700e_description/meshes/link7.STL" />
      </geometry>
      <material name="">
        <color rgba="0.752941176470588 0.752941176470588 0.752941176470588 1" />
      </material>
    </visual>
    <collision>
      <origin xyz="0 0 0" rpy="0 0 0" />
      <geometry>
        <mesh filename="package://robot_sd700e_description/meshes/link7.STL" />
      </geometry>
    </collision>
  </link>
  <joint name="joint7" type="fixed">
    <origin xyz="0 0 0" rpy="0 0 0" />
    <parent link="link6" />
    <child link="link7" />
    <axis xyz="0 0 0" />
  </joint>

  <!-- Transmissions for ROS Control -->
  <xacro:macro name="transmission_block" params="joint_name">
    <transmission name="tran1">
      <type>transmission_interface/SimpleTransmission</type>
      <joint name="${joint_name}">
        <hardwareInterface>hardware_interface/PositionJointInterface</hardwareInterface>
      </joint>
      <actuator name="motor1">
        <hardwareInterface>hardware_interface/PositionJointInterface</hardwareInterface>
        <mechanicalReduction>1</mechanicalReduction>
      </actuator>
    </transmission>
  </xacro:macro>
  
  <xacro:transmission_block joint_name="joint1"/>
  <xacro:transmission_block joint_name="joint2"/>
  <xacro:transmission_block joint_name="joint3"/>
  <xacro:transmission_block joint_name="joint4"/>
  <xacro:transmission_block joint_name="joint5"/>
  <xacro:transmission_block joint_name="joint6"/>

  <!-- ros_control plugin -->
  <gazebo>
    <plugin name="gazebo_ros_control" filename="libgazebo_ros_control.so">
      <robotNamespace>/robot_sd700e</robotNamespace>
      <robotSimType>gazebo_ros_control/DefaultRobotHWSim</robotSimType>
      <legacyModeNS>true</legacyModeNS>
    </plugin>
  </gazebo>

</robot>
